Workbook

Sheet Toelichting
A1: SOK Amsterdam - Asfalt 2026 — calculatiebasis
A3: Herkomst van de gegevens
A4: Uitgelezen uit drie rapporten van Gemeente Amsterdam: Asfalt Schouw NOORD (26-08-2026, 49 pagina's),
A5: Notities Asfalt NOORD 2026 en Herstelwerkzaamheden Noord.
A6: Coordinaten zijn letterlijk overgenomen uit de GPS-regel van het rapport.
A8: Werksoort
A9: Staat met de hand in de kantlijn van de rapporten: HB = hotbox, AS = asfalt machinaal.
A10: Die codes zijn per melding van de scan afgelezen en visueel nagelopen.
A11: Bij de herstelpunten van de nutsbedrijven staat geen code; daar noemt de tekst de asfaltsoort.
A12: Zonder code en zonder asfaltsoort blijft de melding 'nog in te delen' — er is niets ingevuld
A13: wat niet in de bron staat.
A14: Kolom 'Waarom deze werksoort' op het blad Locaties zegt per regel waar de indeling vandaan komt.
... A48: scripts/maak_calculatie_excel.py. Verandert de dataset, draai dat script opnieuw.

Sheet Tarieven
A1: Tarieven per werksoort — de blauwe cellen zijn invoer
A3: Werksoort | B3: Rekeneenheid | C3: Tarief min | D3: Tarief max | E3: Herkomst startwaarde
A4: Hotbox werkzaamheden | B4: plek | C4: 150 | D4: 400 | E4: €150–400 / plek
A5: Asfalt machinaal | B5: m2 | C5: 20 | D5: 40 | E5: €20–40 / m²
A6: Scheuren vullen | B6: m1 | C6: 5 | D6: 15 | E6: €5–15 / m¹
A7: Asfalt – nog in te delen | B7: m2 | C7: 0 | D7: 0 | E7: geen tarief — werksoort nog niet bepaald
A9: Startwaarden: CROW-kostenkengetallen (crow_kosten.py). Orde van grootte, geen offerte.

Sheet Locaties
A1: Referentie | B1: Werksoort | C1: Straat | D1: Buurt | E1: Wat is er geschouwd | F1: Maatvoering | G1: Aantal vlakken | H1: Lengte (m) | I1: Kleinste breedte (m) | J1: Oppervlak (m2) | K1: Rekeneenheid | L1: Hoeveelheid | M1: Tarief min | N1: Tarief max | O1: Kosten min | P1: Kosten max | Q1: Prioriteit | R1: Schouwdatum | S1: Week | T1: GPS breedte | U1: GPS lengte | V1: Adres bij GPS | W1: Bron | X1: Pagina | Y1: Foto | Z1: Waarom deze werksoort | AA1: Let op | AB1: Asset-code (weg) | AC1: Asfaltsoort | AD1: Aantal foto's
A2: SOK-AMS-2026-001 | B2: Asfalt – nog in te delen | C2: Oostzanerdijk | D2: Oostzanerwerf | E2: 7.60 x 0.30 | F2: 7,60 × 0,30 m (samen 2,3 m²) | G2: 1 | H2: 7.6 | I2: 0.3 | J2: 2.28 | K2: =INDEX(Tarieven!$A$4:$E$7,MATCH($B2,Tarieven!$A$4:$A$7,0),2) | L2: =IF($K2="plek",$G2,IF($K2="m1",$H2,$J2)) | M2: =INDEX(Tarieven!$A$4:$E$7,MATCH($B2,Tarieven!$A$4:$A$7,0),3) | N2: =INDEX(Tarieven!$A$4:$E$7,MATCH($B2,Tarieven!$A$4:$A$7,0),4) | O2: =IFERROR($L2*$M2,0) | P2: =IFERROR($L2*$N2,0) | Q2: normaal | R2: 2026-06-08 | S2: 24 | T2: 52.421 | U2: 4.87833 | V2: Oostzanerdijk 141A, Amsterdam | W2: Asfalt Schouw NOORD — 26 augustus 2026 | X2: 1/49 | Y2: 001-oostzanerdijk.jpg | Z2: geen code in de kantlijn en geen asfaltsoort in de tekst | AB2: SOK-AMS-OOSTZANERDIJK | AD2: 1
A3: SOK-AMS-2026-002 | B3: Asfalt – nog in te delen | C3: Oostzanerdijk | D3: Oostzanerwerf | E3: 8.00 x 0.30 | F3: 8,00 × 0,30 m (samen 2,4 m²) | G3: 1 | H3: 8 | I3: 0.3 | J3: 2.4 | K3: =INDEX(Tarieven!$A$4:$E$7,MATCH($B3,Tarieven!$A$4:$A$7,0),2) | L3: =IF($K3="plek",$G3,IF($K3="m1",$H3,$J3)) | M3: =INDEX(Tarieven!$A$4:$E$7,MATCH($B3,Tarieven!$A$4:$A$7,0),3) | N3: =INDEX(Tarieven!$A$4:$E$7,MATCH($B3,Tarieven!$A$4:$A$7,0),4) | O3: =IFERROR($L3*$M3,0) | P3: =IFERROR($L3*$N3,0) | Q3: normaal | R3: 2026-06-08 | S3: 24 | T3: 52.4205 | U3: 4.87857 | V3: Oostzanerdijk 139, Amsterdam | W3: Asfalt Schouw NOORD — 26 augustus 2026 | X3: 1/49 | Y3: 002-oostzanerdijk.jpg | Z3: geen code in de kantlijn en geen asfaltsoort in de tekst | AB3: SOK-AMS-OOSTZANERDIJK | AD3: 1
A4: SOK-AMS-2026-003 | B4: Asfalt – nog in te delen | C4: Stellingweg | D4: Oostzanerwerf | E4: Stellingenweg t.h.v. 202 | G4: 0 | K4: =INDEX(Tarieven!$A$4:$E$7,MATCH($B4,Tarieven!$A$4:$A$7,0),2) | L4: =IF($K4="plek",$G4,IF($K4="m1",$H4,$J4)) | M4: =INDEX(Tarieven!$A$4:$E$7,MATCH($B4,Tarieven!$A$4:$A$7,0),3) | N4: =INDEX(Tarieven!$A$4:$E$7,MATCH($B4,Tarieven!$A$4:$A$7,0),4) | O4: =IFERROR($L4*$M4,0) | P4: =IFERROR($L4*$N4,0) | Q4: normaal | R4: 2026-06-08 | S4: 24 | T4: 52.38688 | U4: 4.90561 | V4: Céramiquelaan 723, Amsterdam | W4: Asfalt Schouw NOORD — 26 augustus 2026 | X4: 1/49 | Y4: 003-stellingweg.jpg | Z4: geen code in de kantlijn en geen asfaltsoort in de tekst | AA4: Coordinaat ligt 3.4 km van de overige punten op Stellingweg — het adres in het rapport (Céramiquelaan 723, Amsterdam) hoort bij een andere buurt. Controleer dit punt op de kaart. · geen maatvoering in de bron | AB4: SOK-AMS-STELLINGWEG | AD4: 1
A5: SOK-AMS-2026-004 | B5: Asfalt – nog in te delen | C5: Stellingweg | D5: Oostzanerwerf | E5: Stellingweg t.h.v. 202 0.80x 0.80 | F5: 0,80 × 0,80 m (samen 0,6 m²) | G5: 1 | H5: 0.8 | I5: 0.8 | J5: 0.64 | K5: =INDEX(Tarieven!$A$4:$E$7,MATCH($B5,Tarieven!$A$4:$A$7,0),2) | L5: =IF($K5="plek",$G5,IF($K5="m1",$H5,$J5)) | M5: =INDEX(Tarieven!$A$4:$E$7,MATCH($B5,Tarieven!$A$4:$A$7,0),3) | N5: =INDEX(Tarieven!$A$4:$E$7,MATCH($B5,Tarieven!$A$4:$A$7,0),4) | O5: =IFERROR($L5*$M5,0) | P5: =IFERROR($L5*$N5,0) | Q5: normaal | R5: 2026-06-08 | S5: 24 | T5: 52.41686 | U5: 4.89436 | V5: Stellingweg 169A, Amsterdam | W5: Asfalt Schouw NOORD — 26 augustus 2026 | X5: 2/49 | Y5: 004-stellingweg.jpg | Z5: geen code in de kantlijn en geen asfaltsoort in de tekst | AB5: SOK-AMS-STELLINGWEG | AD5: 1
A6: SOK-AMS-2026-005 | B6: Asfalt – nog in te delen | C6: Stellingweg | E6: Stellingweg 27/153 _ 4.80 x 0.90 | F6: 4,80 × 0,90 m (samen 4,3 m²) | G6: 1 | H6: 4.8 | I6: 0.9 | J6: 4.32 | K6: =INDEX(Tarieven!$A$4:$E$7,MATCH($B6,Tarieven!$A$4:$A$7,0),2) | L6: =IF($K6="plek",$G6,IF($K6="m1",$H6,$J6)) | M6: =INDEX(Tarieven!$A$4:$E$7,MATCH($B6,Tarieven!$A$4:$A$7,0),3) | N6: =INDEX(Tarieven!$A$4:$E$7,MATCH($B6,Tarieven!$A$4:$A$7,0),4) | O6: =IFERROR($L6*$M6,0) | P6: =IFERROR($L6*$N6,0) | Q6: normaal | R6: 2026-06-08 | S6: 24 | T6: 52.41717 | U6: 4.89436 | V6: Stellingweg 159, Amsterdam | W6: Asfalt Schouw NOORD — 26 augustus 2026 | X6: 2/49 | Y6: 005-stellingweg.jpg | Z6: geen code in de kantlijn en geen asfaltsoort in de tekst | AB6: SOK-AMS-STELLINGWEG | AD6: 1
A7: SOK-AMS-2026-006 | B7: Asfalt – nog in te delen | C7: Zuideinde | D7: Oostzanerwerf | E7: Zuideinde 509 3.80 x 1.40 + 2.40 x 1.30 | F7: 3,80 × 1,40 m + 2,40 × 1,30 m (samen 8,4 m²) | G7: 2 | H7: 6.2 | I7: 1.3 | J7: 8.44 | K7: =INDEX(Tarieven!$A$4:$E$7,MATCH($B7,Tarieven!$A$4:$A$7,0),2) | L7: =IF($K7="plek",$G7,IF($K7="m1",$H7,$J7)) | M7: =INDEX(Tarieven!$A$4:$E$7,MATCH($B7,Tarieven!$A$4:$A$7,0),3) | N7: =INDEX(Tarieven!$A$4:$E$7,MATCH($B7,Tarieven!$A$4:$A$7,0),4) | O7: =IFERROR($L7*$M7,0) | P7: =IFERROR($L7*$N7,0) | Q7: normaal | R7: 2026-06-08 | S7: 24 | T7: 52.4167 | U7: 4.89654 | V7: Zuideinde 503, Amsterdam | W7: Asfalt Schouw NOORD — 26 augustus 2026 | X7: 2/49 | Y7: 006-zuideinde.jpg | Z7: geen code in de kantlijn en geen asfaltsoort in de tekst | AB7: SOK-AMS-ZUIDEINDE | AD7: 2
A8: SOK-AMS-2026-007 | B8: Hotbox werkzaamheden | C8: Zuideinde | E8: Zuideinde 491 _ 1.70 x 1.40 | F8: 1,70 × 1,40 m (samen 2,4 m²) | G8: 1 | H8: 1.7 | I8: 1.4 | J8: 2.38 | K8: =INDEX(Tarieven!$A$4:$E$7,MATCH($B8,Tarieven!$A$4:$A$7,0),2) | L8: =IF($K8="plek",$G8,IF($K8="m1",$H8,$J8)) | M8: =INDEX(Tarieven!$A$4:$E$7,MATCH($B8,Tarieven!$A$4:$A$7,0),3) | N8: =INDEX(Tarieven!$A$4:$E$7,MATCH($B8,Tarieven!$A$4:$A$7,0),4) | O8: =IFERROR($L8*$M8,0) | P8: =IFERROR($L8*$N8,0) | Q8: normaal | R8: 2026-06-08 | S8: 24 | T8: 52.41731 | U8: 4.89603 | V8: Zuideinde 489, Amsterdam | W8: Asfalt Schouw NOORD — 26 augustus 2026 | X8: 2/49 | Y8: 007-zuideinde.jpg | Z8: handgeschreven code "HB" in de kantlijn | AB8: SOK-AMS-ZUIDEINDE | AD8: 1
A9: SOK-AMS-2026-008 | B9: Hotbox werkzaamheden | C9: Zuideinde | E9: Zuideinde 485 - 1.10 x 1.00 | F9: 1,10 × 1,00 m (samen 1,1 m²) | G9: 1 | H9: 1.1 | I9: 1 | J9: 1.1 | K9: =INDEX(Tarieven!$A$4:$E$7,MATCH($B9,Tarieven!$A$4:$A$7,0),2) | L9: =IF($K9="plek",$G9,IF($K9="m1",$H9,$J9)) | M9: =INDEX(Tarieven!$A$4:$E$7,MATCH($B9,Tarieven!$A$4:$A$7,0),3) | N9: =INDEX(Tarieven!$A$4:$E$7,MATCH($B9,Tarieven!$A$4:$A$7,0),4) | O9: =IFERROR($L9*$M9,0) | P9: =IFERROR($L9*$N9,0) | Q9: normaal | R9: 2026-06-08 | S9: 24 | T9: 52.41731 | U9: 4.89603 | V9: Zuideinde 489, Amsterdam | W9: Asfalt Schouw NOORD — 26 augustus 2026 | X9: 3/49 | Y9: 008-zuideinde.jpg | Z9: handgeschreven code "HB" in de kantlijn | AB9: SOK-AMS-ZUIDEINDE | AD9: 1
A10: SOK-AMS-2026-009 | B10: Hotbox werkzaamheden | C10: Zuideinde | D10: Oostzanerwerf | E10: Zuideinde 393 - 3.60 x 1.40 | F10: 3,60 × 1,40 m (samen 5,0 m²) | G10: 1 | H10: 3.6 | I10: 1.4 | J10: 5.04 | K10: =INDEX(Tarieven!$A$4:$E$7,MATCH($B10,Tarieven!$A$4:$A$7,0),2) | L10: =IF($K10="plek",$G10,IF($K10="m1",$H10,$J10)) | M10: =INDEX(Tarieven!$A$4:$E$7,MATCH($B10,Tarieven!$A$4:$A$7,0),3) | N10: =INDEX(Tarieven!$A$4:$E$7,MATCH($B10,Tarieven!$A$4:$A$7,0),4) | O10: =IFERROR($L10*$M10,0) | P10: =IFERROR($L10*$N10,0) | Q10: normaal | R10: 2026-06-08 | S10: 24 | T10: 52.41737 | U10: 4.89546 | V10: Zuideinde 412, Amsterdam | W10: Asfalt Schouw NOORD — 26 augustus 2026 | X10: 3/49 | Y10: 009-zuideinde.jpg | Z10: handgeschreven code "HB" in de kantlijn | AB10: SOK-AMS-ZUIDEINDE | AD10: 1
A11: SOK-AMS-2026-010 | B11: Hotbox werkzaamheden | C11: Zuideinde | D11: Oostzanerwerf | E11: Zuideinde 333 - 1.70 x 1.20 | F11: 1,70 × 1,20 m (samen 2,0 m²) | G11: 1 | H11: 1.7 | I11: 1.2 | J11: 2.04 | K11: =INDEX(Tarieven!$A$4:$E$7,MATCH($B11,Tarieven!$A$4:$A$7,0),2) | L11: =IF($K11="plek",$G11,IF($K11="m1",$H11,$J11)) | M11: =INDEX(Tarieven!$A$4:$E$7,MATCH($B11,Tarieven!$A$4:$A$7,0),3) | N11: =INDEX(Tarieven!$A$4:$E$7,MATCH($B11,Tarieven!$A$4:$A$7,0),4) | O11: =IFERROR($L11*$M11,0) | P11: =IFERROR($L11*$N11,0) | Q11: normaal | R11: 2026-06-08 | S11: 24 | T11: 52.42366 | U11: 4.8898 | V11: Zuideinde 333, Amsterdam | W11: Asfalt Schouw NOORD — 26 augustus 2026 | X11: 3/49 | Y11: 010-zuideinde.jpg | Z11: handgeschreven code "HB" in de kantlijn | AB11: SOK-AMS-ZUIDEINDE | AD11: 1
A12: SOK-AMS-2026-011 | B12: Hotbox werkzaamheden | C12: Zuideinde | D12: Oostzanerwerf | E12: Zuideinde 355 - 3.70 x 1.40 | F12: 3,70 × 1,40 m (samen 5,2 m²) | G12: 1 | H12: 3.7 | I12: 1.4 | J12: 5.18 | K12: =INDEX(Tarieven!$A$4:$E$7,MATCH($B12,Tarieven!$A$4:$A$7,0),2) | L12: =IF($K12="plek",$G12,IF($K12="m1",$H12,$J12)) | M12: =INDEX(Tarieven!$A$4:$E$7,MATCH($B12,Tarieven!$A$4:$A$7,0),3) | N12: =INDEX(Tarieven!$A$4:$E$7,MATCH($B12,Tarieven!$A$4:$A$7,0),4) | O12: =IFERROR($L12*$M12,0) | P12: =IFERROR($L12*$N12,0) | Q12: normaal | R12: 2026-06-08 | S12: 24 | T12: 52.42348 | U12: 4.88993 | V12: Zuideinde 339, Amsterdam | W12: Asfalt Schouw NOORD — 26 augustus 2026 | X12: 4/49 | Y12: 011-zuideinde.jpg | Z12: handgeschreven code "HB" in de kantlijn | AB12: SOK-AMS-ZUIDEINDE | AD12: 1
A13: SOK-AMS-2026-012 | B13: Hotbox werkzaamheden | C13: Cornelis Roosstraat | D13: Oostzanerwerf | E13: C.roosstr 5 - 5.00 x 0.50 | F13: 5,00 × 0,50 m (samen 2,5 m²) | G13: 1 | H13: 5 | I13: 0.5 | J13: 2.5 | K13: =INDEX(Tarieven!$A$4:$E$7,MATCH($B13,Tarieven!$A$4:$A$7,0),2) | L13: =IF($K13="plek",$G13,IF($K13="m1",$H13,$J13)) | M13: =INDEX(Tarieven!$A$4:$E$7,MATCH($B13,Tarieven!$A$4:$A$7,0),3) | N13: =INDEX(Tarieven!$A$4:$E$7,MATCH($B13,Tarieven!$A$4:$A$7,0),4) | O13: =IFERROR($L13*$M13,0) | P13: =IFERROR($L13*$N13,0) | Q13: normaal | R13: 2026-06-08 | S13: 24 | T13: 52.41911 | U13: 4.8963 | V13: Cornelis Roosstraat 2, Amsterdam | W13: Asfalt Schouw NOORD — 26 augustus 2026 | X13: 4/49 | Y13: 012-cornelisroosstraat.jpg | Z13: handgeschreven code "HB" in de kantlijn | AB13: SOK-AMS-CORNELIS-ROOSSTRAAT | AD13: 1
A14: SOK-AMS-2026-013 | B14: Asfalt – nog in te delen | C14: Cornelis Roosstraat | D14: Oostzanerwerf | E14: C.roosstr t/o 25 - 3.00 x 1.10 | F14: 3,00 × 1,10 m (samen 3,3 m²) | G14: 1 | H14: 3 | I14: 1.1 | J14: 3.3 | K14: =INDEX(Tarieven!$A$4:$E$7,MATCH($B14,Tarieven!$A$4:$A$7,0),2) | L14: =IF($K14="plek",$G14,IF($K14="m1",$H14,$J14)) | M14: =INDEX(Tarieven!$A$4:$E$7,MATCH($B14,Tarieven!$A$4:$A$7,0),3) | N14: =INDEX(Tarieven!$A$4:$E$7,MATCH($B14,Tarieven!$A$4:$A$7,0),4) | O14: =IFERROR($L14*$M14,0) | P14: =IFERROR($L14*$N14,0) | Q14: normaal | R14: 2026-06-08 | S14: 24 | T14: 52.41867 | U14: 4.89694 | V14: Cornelis Roosstraat 23, Amsterdam | W14: Asfalt Schouw NOORD — 26 augustus 2026 | X14: 4/49 | Y14: 013-cornelisroosstraat.jpg | Z14: geen code in de kantlijn en geen asfaltsoort in de tekst | AB14: SOK-AMS-CORNELIS-ROOSSTRAAT | AD14: 1
A15: SOK-AMS-2026-014 | B15: Asfalt – nog in te delen | C15: Cornelis Roosstraat | D15: Oostzanerwerf | E15: C.roosstr t.h.v. 27 _ 11.00 x 0.40 | F15: 11,00 × 0,40 m (samen 4,4 m²) | G15: 1 | H15: 11 | I15: 0.4 | J15: 4.4 | K15: =INDEX(Tarieven!$A$4:$E$7,MATCH($B15,Tarieven!$A$4:$A$7,0),2) | L15: =IF($K15="plek",$G15,IF($K15="m1",$H15,$J15)) | M15: =INDEX(Tarieven!$A$4:$E$7,MATCH($B15,Tarieven!$A$4:$A$7,0),3) | N15: =INDEX(Tarieven!$A$4:$E$7,MATCH($B15,Tarieven!$A$4:$A$7,0),4) | O15: =IFERROR($L15*$M15,0) | P15: =IFERROR($L15*$N15,0) | Q15: normaal | R15: 2026-06-08 | S15: 24 | T15: 52.4183 | U15: 4.89678 | V15: Cornelis Roosstraat 27, Amsterdam | W15: Asfalt Schouw NOORD — 26 augustus 2026 | X15: 5/49 | Y15: 014-cornelisroosstraat.jpg | Z15: geen code in de kantlijn en geen asfaltsoort in de tekst | AB15: SOK-AMS-CORNELIS-ROOSSTRAAT | AD15: 1
A16: SOK-AMS-2026-015 | B16: Asfalt – nog in te delen | C16: Cornelis Roosstraat | D16: Oostzanerwerf | E16: C.roosstr t.h.v. oplaadpunt 5.00x 0.40 | F16: 5,00 × 0,40 m (samen 2,0 m²) | G16: 1 | H16: 5 | I16: 0.4 | J16: 2 | K16: =INDEX(Tarieven!$A$4:$E$7,MATCH($B16,Tarieven!$A$4:$A$7,0),2) | L16: =IF($K16="plek",$G16,IF($K16="m1",$H16,$J16)) | M16: =INDEX(Tarieven!$A$4:$E$7,MATCH($B16,Tarieven!$A$4:$A$7,0),3) | N16: =INDEX(Tarieven!$A$4:$E$7,MATCH($B16,Tarieven!$A$4:$A$7,0),4) | O16: =IFERROR($L16*$M16,0) | P16: =IFERROR($L16*$N16,0) | Q16: normaal | R16: 2026-06-08 | S16: 24 | T16: 52.4183 | U16: 4.89678 | V16: Cornelis Roosstraat 27, Amsterdam | W16: Asfalt Schouw NOORD — 26 augustus 2026 | X16: 5/49 | Y16: 015-cornelisroosstraat.jpg | Z16: geen code in de kantlijn en geen asfaltsoort in de tekst | AB16: SOK-AMS-CORNELIS-ROOSSTRAAT | AD16: 1
A17: SOK-AMS-2026-016 | B17: Hotbox werkzaamheden | C17: Molenwijk | D17: Oostzanerwerf | E17: 2.60 x 1.80 + 9.00 x 1.80 parkeerplaats molenwijk | F17: 2,60 × 1,80 m + 9,00 × 1,80 m (samen 20,9 m²) | G17: 2 | H17: 11.6 | I17: 1.8 | J17: 20.88 | K17: =INDEX(Tarieven!$A$4:$E$7,MATCH($B17,Tarieven!$A$4:$A$7,0),2) | L17: =IF($K17="plek",$G17,IF($K17="m1",$H17,$J17)) | M17: =INDEX(Tarieven!$A$4:$E$7,MATCH($B17,Tarieven!$A$4:$A$7,0),3) | N17: =INDEX(Tarieven!$A$4:$E$7,MATCH($B17,Tarieven!$A$4:$A$7,0),4) | O17: =IFERROR($L17*$M17,0) | P17: =IFERROR($L17*$N17,0) | Q17: normaal | R17: 2026-06-08 | S17: 24 | T17: 52.41797 | U17: 4.89378 | V17: Amsterdam | W17: Asfalt Schouw NOORD — 26 augustus 2026 | X17: 5/49 | Y17: 016-molenwijk.jpg | Z17: handgeschreven code "HB" in de kantlijn | AB17: SOK-AMS-MOLENWIJK | AD17: 2
A18: SOK-AMS-2026-017 | B18: Asfalt machinaal | C18: Sportpark Oostzanerwerf | D18: Asfalt Schades Heel Noord | E18: 50.00 x 3.00 verzakt en scheuren. Dit gedeelte maakt deel uit van een dijk | F18: 50,00 × 3,00 m (samen 150,0 m²) | G18: 1 | H18: 50 | I18: 3 | J18: 150 | K18: =INDEX(Tarieven!$A$4:$E$7,MATCH($B18,Tarieven!$A$4:$A$7,0),2) | L18: =IF($K18="plek",$G18,IF($K18="m1",$H18,$J18)) | M18: =INDEX(Tarieven!$A$4:$E$7,MATCH($B18,Tarieven!$A$4:$A$7,0),3) | N18: =INDEX(Tarieven!$A$4:$E$7,MATCH($B18,Tarieven!$A$4:$A$7,0),4) | O18: =IFERROR($L18*$M18,0) | P18: =IFERROR($L18*$N18,0) | Q18: normaal | R18: 2026-06-09 | S18: 24 | T18: 52.42157 | U18: 4.87895 | V18: Sportpark Oostzanerwerf 4, Amsterdam | W18: Asfalt Schouw NOORD — 26 augustus 2026 | X18: 6/49 | Y18: 017-sportparkoostzanerwerf.jpg | Z18: handgeschreven code "AS" in de kantlijn | AB18: SOK-AMS-SPORTPARK-OOSTZANERWERF | AD18: 2
A19: SOK-AMS-2026-018 | B19: Asfalt machinaal | C19: Oostzanerdijk | D19: Asfalt Schades Heel Noord | E19: 6.00 x 3.00 Oostzanerdijk / molenaarsweg | F19: 6,00 × 3,00 m (samen 18,0 m²) | G19: 1 | H19: 6 | I19: 3 | J19: 18 | K19: =INDEX(Tarieven!$A$4:$E$7,MATCH($B19,Tarieven!$A$4:$A$7,0),2) | L19: =IF($K19="plek",$G19,IF($K19="m1",$H19,$J19)) | M19: =INDEX(Tarieven!$A$4:$E$7,MATCH($B19,Tarieven!$A$4:$A$7,0),3) | N19: =INDEX(Tarieven!$A$4:$E$7,MATCH($B19,Tarieven!$A$4:$A$7,0),4) | O19: =IFERROR($L19*$M19,0) | P19: =IFERROR($L19*$N19,0) | Q19: normaal | R19: 2026-06-09 | S19: 24 | T19: 52.4205 | U19: 4.87857 | V19: Oostzanerdijk 139, Amsterdam | W19: Asfalt Schouw NOORD — 26 augustus 2026 | X19: 6/49 | Y19: 018-oostzanerdijk.jpg | Z19: handgeschreven code "AS" in de kantlijn | AB19: SOK-AMS-OOSTZANERDIJK | AD19: 1
A20: SOK-AMS-2026-019 | B20: Hotbox werkzaamheden | C20: Molenaarsweg | D20: Asfalt Schades Heel Noord | E20: Molenaarsweg / oostzanerwerf 2x 2.00 x 0.50 | F20: 2× 2,00 × 0,50 m (samen 2,0 m²) | G20: 2 | H20: 4 | I20: 0.5 | J20: 2 | K20: =INDEX(Tarieven!$A$4:$E$7,MATCH($B20,Tarieven!$A$4:$A$7,0),2) | L20: =IF($K20="plek",$G20,IF($K20="m1",$H20,$J20)) | M20: =INDEX(Tarieven!$A$4:$E$7,MATCH($B20,Tarieven!$A$4:$A$7,0),3) | N20: =INDEX(Tarieven!$A$4:$E$7,MATCH($B20,Tarieven!$A$4:$A$7,0),4) | O20: =IFERROR($L20*$M20,0) | P20: =IFERROR($L20*$N20,0) | Q20: normaal | R20: 2026-06-09 | S20: 24 | T20: 52.42115 | U20: 4.88785 | V20: Grondzeiler 1, Amsterdam | W20: Asfalt Schouw NOORD — 26 augustus 2026 | X20: 7/49 | Y20: 019-molenaarsweg.jpg | Z20: handgeschreven code "HB" in de kantlijn | AB20: SOK-AMS-MOLENAARSWEG | AD20: 1
A21: SOK-AMS-2026-020 | B21: Asfalt – nog in te delen | C21: Molenaarsweg | D21: Asfalt Schades Heel Noord | E21: 15.00 x 0.50 scheuren. 3.00 x 0.50 gevaarlijk gat Molenaarsweg. Voor de bocht Zuideinde | F21: 15,00 × 0,50 m + 3,00 × 0,50 m (samen 9,0 m²) | G21: 2 | H21: 18 | I21: 0.5 | J21: 9 | K21: =INDEX(Tarieven!$A$4:$E$7,MATCH($B21,Tarieven!$A$4:$A$7,0),2) | L21: =IF($K21="plek",$G21,IF($K21="m1",$H21,$J21)) | M21: =INDEX(Tarieven!$A$4:$E$7,MATCH($B21,Tarieven!$A$4:$A$7,0),3) | N21: =INDEX(Tarieven!$A$4:$E$7,MATCH($B21,Tarieven!$A$4:$A$7,0),4) | O21: =IFERROR($L21*$M21,0) | P21: =IFERROR($L21*$N21,0) | Q21: normaal | R21: 2026-06-09 | S21: 24 | T21: 52.42203 | U21: 4.88909 | V21: Tuimelaarstraat 3, Amsterdam | W21: Asfalt Schouw NOORD — 26 augustus 2026 | X21: 7/49 | Y21: 020-molenaarsweg.jpg | Z21: in het rapport groen doorgestreept — werksoort onduidelijk | AB21: SOK-AMS-MOLENAARSWEG | AD21: 2
A22: SOK-AMS-2026-021 | B22: Asfalt – nog in te delen | C22: Molenaarsweg | D22: Asfalt Schades Heel Noord | E22: 37.00 x o.50 Molenaarsweg bocht voor zuideinde | G22: 0 | K22: =INDEX(Tarieven!$A$4:$E$7,MATCH($B22,Tarieven!$A$4:$A$7,0),2) | L22: =IF($K22="plek",$G22,IF($K22="m1",$H22,$J22)) | M22: =INDEX(Tarieven!$A$4:$E$7,MATCH($B22,Tarieven!$A$4:$A$7,0),3) | N22: =INDEX(Tarieven!$A$4:$E$7,MATCH($B22,Tarieven!$A$4:$A$7,0),4) | O22: =IFERROR($L22*$M22,0) | P22: =IFERROR($L22*$N22,0) | Q22: normaal | R22: 2026-06-09 | S22: 24 | T22: 52.41985 | U22: 4.89196 | V22: Molenwijk 8, Amsterdam | W22: Asfalt Schouw NOORD — 26 augustus 2026 | X22: 7/49 | Y22: 021-molenaarsweg.jpg | Z22: in het rapport groen doorgestreept — werksoort onduidelijk | AA22: geen maatvoering in de bron | AB22: SOK-AMS-MOLENAARSWEG | AD22: 2
A23: SOK-AMS-2026-022 | B23: Asfalt – nog in te delen | C23: Meteorenweg | D23: Tuindorp Oostzaan | E23: 1.70 x 1.60 + 3.30 x 0.90 Meteorenweg / Aldebaranstr | F23: 1,70 × 1,60 m + 3,30 × 0,90 m (samen 5,7 m²) | G23: 2 | H23: 5 | I23: 0.9 | J23: 5.69 | K23: =INDEX(Tarieven!$A$4:$E$7,MATCH($B23,Tarieven!$A$4:$A$7,0),2) | L23: =IF($K23="plek",$G23,IF($K23="m1",$H23,$J23)) | M23: =INDEX(Tarieven!$A$4:$E$7,MATCH($B23,Tarieven!$A$4:$A$7,0),3) | N23: =INDEX(Tarieven!$A$4:$E$7,MATCH($B23,Tarieven!$A$4:$A$7,0),4) | O23: =IFERROR($L23*$M23,0) | P23: =IFERROR($L23*$N23,0) | Q23: normaal | R23: 2026-06-09 | S23: 24 | T23: 52.41084 | U23: 4.89062 | V23: Aldebaranstraat 1, Amsterdam | W23: Asfalt Schouw NOORD — 26 augustus 2026 | X23: 7/49 | Y23: 022-meteorenweg.jpg | Z23: geen code in de kantlijn en geen asfaltsoort in de tekst | AB23: SOK-AMS-METEORENWEG | AD23: 1
A24: SOK-AMS-2026-023 | B24: Asfalt – nog in te delen | C24: Aldebaranstraat | D24: Tuindorp Oostzaan | E24: 51.00 x 1.00 Aldebaranstr nr 13 tot Meteorenweg | F24: 51,00 × 1,00 m (samen 51,0 m²) | G24: 1 | H24: 51 | I24: 1 | J24: 51 | K24: =INDEX(Tarieven!$A$4:$E$7,MATCH($B24,Tarieven!$A$4:$A$7,0),2) | L24: =IF($K24="plek",$G24,IF($K24="m1",$H24,$J24)) | M24: =INDEX(Tarieven!$A$4:$E$7,MATCH($B24,Tarieven!$A$4:$A$7,0),3) | N24: =INDEX(Tarieven!$A$4:$E$7,MATCH($B24,Tarieven!$A$4:$A$7,0),4) | O24: =IFERROR($L24*$M24,0) | P24: =IFERROR($L24*$N24,0) | Q24: normaal | R24: 2026-06-09 | S24: 24 | T24: 52.41084 | U24: 4.89062 | V24: Aldebaranstraat 1, Amsterdam | W24: Asfalt Schouw NOORD — 26 augustus 2026 | X24: 8/49 | Y24: 023-aldebaranstraat.jpg | Z24: geen code in de kantlijn en geen asfaltsoort in de tekst | AB24: SOK-AMS-ALDEBARANSTRAAT | AD24: 1
A25: SOK-AMS-2026-024 | B25: Asfalt – nog in te delen | C25: Aldebaranstraat | D25: Tuindorp Oostzaan | E25: Rigelstraat van nr 3 tot Aldebaranstr 18 00 x 0.80 | G25: 0 | K25: =INDEX(Tarieven!$A$4:$E$7,MATCH($B25,Tarieven!$A$4:$A$7,0),2) | L25: =IF($K25="plek",$G25,IF($K25="m1",$H25,$J25)) | M25: =INDEX(Tarieven!$A$4:$E$7,MATCH($B25,Tarieven!$A$4:$A$7,0),3) | N25: =INDEX(Tarieven!$A$4:$E$7,MATCH($B25,Tarieven!$A$4:$A$7,0),4) | O25: =IFERROR($L25*$M25,0) | P25: =IFERROR($L25*$N25,0) | Q25: normaal | R25: 2026-06-09 | S25: 24 | T25: 52.41114 | U25: 4.89099 | V25: Aldebaranstraat 13, Amsterdam | W25: Asfalt Schouw NOORD — 26 augustus 2026 | X25: 8/49 | Y25: 024-aldebaranstraat.jpg | Z25: geen code in de kantlijn en geen asfaltsoort in de tekst | AA25: geen maatvoering in de bron | AB25: SOK-AMS-ALDEBARANSTRAAT | AD25: 1
A26: SOK-AMS-2026-025 | B26: Hotbox werkzaamheden | C26: Rigelstraat | D26: Tuindorp Oostzaan | E26: Rigelstr nr. 8. 2.40 x 0.30 | F26: 2,40 × 0,30 m (samen 0,7 m²) | G26: 1 | H26: 2.4 | I26: 0.3 | J26: 0.72 | K26: =INDEX(Tarieven!$A$4:$E$7,MATCH($B26,Tarieven!$A$4:$A$7,0),2) | L26: =IF($K26="plek",$G26,IF($K26="m1",$H26,$J26)) | M26: =INDEX(Tarieven!$A$4:$E$7,MATCH($B26,Tarieven!$A$4:$A$7,0),3) | N26: =INDEX(Tarieven!$A$4:$E$7,MATCH($B26,Tarieven!$A$4:$A$7,0),4) | O26: =IFERROR($L26*$M26,0) | P26: =IFERROR($L26*$N26,0) | Q26: normaal | R26: 2026-06-09 | S26: 24 | T26: 52.4112 | U26: 4.89043 | V26: Rigelstraat 9, Amsterdam | W26: Asfalt Schouw NOORD — 26 augustus 2026 | X26: 9/49 | Y26: 025-rigelstraat.jpg | Z26: handgeschreven code "HB" in de kantlijn | AB26: SOK-AMS-RIGELSTRAAT | AD26: 1
A27: SOK-AMS-2026-026 | B27: Hotbox werkzaamheden | C27: Rigelstraat | D27: Tuindorp Oostzaan | E27: Rigelstr nr. 8 tot nr. 10 31.50 x 0.70 | F27: 31,50 × 0,70 m (samen 22,0 m²) | G27: 1 | H27: 31.5 | I27: 0.7 | J27: 22.05 | K27: =INDEX(Tarieven!$A$4:$E$7,MATCH($B27,Tarieven!$A$4:$A$7,0),2) | L27: =IF($K27="plek",$G27,IF($K27="m1",$H27,$J27)) | M27: =INDEX(Tarieven!$A$4:$E$7,MATCH($B27,Tarieven!$A$4:$A$7,0),3) | N27: =INDEX(Tarieven!$A$4:$E$7,MATCH($B27,Tarieven!$A$4:$A$7,0),4) | O27: =IFERROR($L27*$M27,0) | P27: =IFERROR($L27*$N27,0) | Q27: normaal | R27: 2026-06-09 | S27: 24 | T27: 52.41204 | U27: 4.88934 | V27: Zonneweg 17, Amsterdam | W27: Asfalt Schouw NOORD — 26 augustus 2026 | X27: 9/49 | Y27: 026-rigelstraat.jpg | Z27: handgeschreven code "HB" in de kantlijn | AB27: SOK-AMS-RIGELSTRAAT | AD27: 1
A28: SOK-AMS-2026-027 | B28: Hotbox werkzaamheden | C28: Zonneweg | D28: Tuindorp Oostzaan | E28: Zonneweg 5.60 1.40 t.h.v. Betelgeuzenstraat foto 1. + 5.90 x 1.40 foto 2. Foto 3 v/a Meteorenweg tot nr 28 Zonnebloemstr. 90.00 x 0.40 | F28: 5,90 × 1,40 m + 90,00 × 0,40 m (samen 44,3 m²) | G28: 2 | H28: 95.9 | I28: 0.4 | J28: 44.26 | K28: =INDEX(Tarieven!$A$4:$E$7,MATCH($B28,Tarieven!$A$4:$A$7,0),2) | L28: =IF($K28="plek",$G28,IF($K28="m1",$H28,$J28)) | M28: =INDEX(Tarieven!$A$4:$E$7,MATCH($B28,Tarieven!$A$4:$A$7,0),3) | N28: =INDEX(Tarieven!$A$4:$E$7,MATCH($B28,Tarieven!$A$4:$A$7,0),4) | O28: =IFERROR($L28*$M28,0) | P28: =IFERROR($L28*$N28,0) | Q28: normaal | R28: 2026-06-09 | S28: 24 | T28: 52.41182 | U28: 4.88947 | V28: Rigelstraat 19, Amsterdam | W28: Asfalt Schouw NOORD — 26 augustus 2026 | X28: 9/49 | Y28: 027-zonneweg.jpg | Z28: handgeschreven code "HB" in de kantlijn | AB28: SOK-AMS-ZONNEWEG | AD28: 3
A29: SOK-AMS-2026-028 | B29: Hotbox werkzaamheden | C29: Meteorenweg | D29: Tuindorp Oostzaan | E29: Meteorenweg / Zonneweg 4.60 x 0.90 + 1.80 x 1.20 | F29: 4,60 × 0,90 m + 1,80 × 1,20 m (samen 6,3 m²) | G29: 2 | H29: 6.4 | I29: 0.9 | J29: 6.3 | K29: =INDEX(Tarieven!$A$4:$E$7,MATCH($B29,Tarieven!$A$4:$A$7,0),2) | L29: =IF($K29="plek",$G29,IF($K29="m1",$H29,$J29)) | M29: =INDEX(Tarieven!$A$4:$E$7,MATCH($B29,Tarieven!$A$4:$A$7,0),3) | N29: =INDEX(Tarieven!$A$4:$E$7,MATCH($B29,Tarieven!$A$4:$A$7,0),4) | O29: =IFERROR($L29*$M29,0) | P29: =IFERROR($L29*$N29,0) | Q29: normaal | R29: 2026-06-09 | S29: 24 | T29: 52.4117 | U29: 4.8889 | V29: Zonneweg 3, Amsterdam | W29: Asfalt Schouw NOORD — 26 augustus 2026 | X29: 10/49 | Y29: 028-meteorenweg.jpg | Z29: handgeschreven code "HB" in de kantlijn | AB29: SOK-AMS-METEORENWEG | AD29: 1
A30: SOK-AMS-2026-029 | B30: Hotbox werkzaamheden | C30: Kometensingel | D30: Tuindorp Oostzaan | E30: Kometensingel v/a nr. 303 tot 265 12 x 2.60 x 0.40 foto 1. Nr. 265 2.20 x 0.90 + 1.80 x 0.60. Foto 3 nr 275 2.00 x 1.40. Foto 4. T/o Neptunusplein 1.60 x 2.00 | F30: 12× 2,60 × 0,40 m + 2,20 × 0,90 m + 1,80 × 0,60 m + 2,00 × 1,40 m + 2,00 × 1,60 m (samen 21,5 m²) | G30: 16 | H30: 39.2 | I30: 0.4 | J30: 21.54 | K30: =INDEX(Tarieven!$A$4:$E$7,MATCH($B30,Tarieven!$A$4:$A$7,0),2) | L30: =IF($K30="plek",$G30,IF($K30="m1",$H30,$J30)) | M30: =INDEX(Tarieven!$A$4:$E$7,MATCH($B30,Tarieven!$A$4:$A$7,0),3) | N30: =INDEX(Tarieven!$A$4:$E$7,MATCH($B30,Tarieven!$A$4:$A$7,0),4) | O30: =IFERROR($L30*$M30,0) | P30: =IFERROR($L30*$N30,0) | Q30: normaal | R30: 2026-06-09 | S30: 24 | T30: 52.41531 | U30: 4.88148 | V30: Kometensingel 303, Amsterdam | W30: Asfalt Schouw NOORD — 26 augustus 2026 | X30: 10/49 | Y30: 029-kometensingel.jpg | Z30: handgeschreven code "HB" in de kantlijn | AB30: SOK-AMS-KOMETENSINGEL | AD30: 4
A31: SOK-AMS-2026-030 | B31: Hotbox werkzaamheden | C31: Kometensingel | D31: Asfalt Schades Heel Noord | E31: Kometensingel 275 4.00 x 1.00 | F31: 4,00 × 1,00 m (samen 4,0 m²) | G31: 1 | H31: 4 | I31: 1 | J31: 4 | K31: =INDEX(Tarieven!$A$4:$E$7,MATCH($B31,Tarieven!$A$4:$A$7,0),2) | L31: =IF($K31="plek",$G31,IF($K31="m1",$H31,$J31)) | M31: =INDEX(Tarieven!$A$4:$E$7,MATCH($B31,Tarieven!$A$4:$A$7,0),3) | N31: =INDEX(Tarieven!$A$4:$E$7,MATCH($B31,Tarieven!$A$4:$A$7,0),4) | O31: =IFERROR($L31*$M31,0) | P31: =IFERROR($L31*$N31,0) | Q31: normaal | R31: 2026-06-09 | S31: 24 | T31: 52.41637 | U31: 4.88233 | V31: Kometensingel 271A, Amsterdam | W31: Asfalt Schouw NOORD — 26 augustus 2026 | X31: 10/49 | Y31: 030-kometensingel.jpg | Z31: handgeschreven code "HB" in de kantlijn | AB31: SOK-AMS-KOMETENSINGEL | AD31: 1
A32: SOK-AMS-2026-031 | B32: Hotbox werkzaamheden | C32: Meteorenweg | D32: Tuindorp Oostzaan | E32: Meteorenweg 267 0.90 x 1.30 | F32: 1,30 × 0,90 m (samen 1,2 m²) | G32: 1 | H32: 1.3 | I32: 0.9 | J32: 1.17 | K32: =INDEX(Tarieven!$A$4:$E$7,MATCH($B32,Tarieven!$A$4:$A$7,0),2) | L32: =IF($K32="plek",$G32,IF($K32="m1",$H32,$J32)) | M32: =INDEX(Tarieven!$A$4:$E$7,MATCH($B32,Tarieven!$A$4:$A$7,0),3) | N32: =INDEX(Tarieven!$A$4:$E$7,MATCH($B32,Tarieven!$A$4:$A$7,0),4) | O32: =IFERROR($L32*$M32,0) | P32: =IFERROR($L32*$N32,0) | Q32: normaal | R32: 2026-06-09 | S32: 24 | T32: 52.41472 | U32: 4.8818 | V32: Meteorenweg 232, Amsterdam | W32: Asfalt Schouw NOORD — 26 augustus 2026 | X32: 11/49 | Y32: 031-meteorenweg.jpg | Z32: handgeschreven code "HB" in de kantlijn | AB32: SOK-AMS-METEORENWEG | AD32: 1
A33: SOK-AMS-2026-032 | B33: Hotbox werkzaamheden | C33: Neptunusstraat | D33: Tuindorp Oostzaan | E33: Neptunusstr nr 332 3.75 x 1.20 foto 1. Foto 2 nr 2 2.50 x 040. Foto 3 nr.8 2.50 x 0.40 | F33: 3,75 × 1,20 m + 40,00 × 2,50 m + 2,50 × 0,40 m (samen 105,5 m²) | G33: 3 | H33: 46.25 | I33: 0.4 | J33: 105.5 | K33: =INDEX(Tarieven!$A$4:$E$7,MATCH($B33,Tarieven!$A$4:$A$7,0),2) | L33: =IF($K33="plek",$G33,IF($K33="m1",$H33,$J33)) | M33: =INDEX(Tarieven!$A$4:$E$7,MATCH($B33,Tarieven!$A$4:$A$7,0),3) | N33: =INDEX(Tarieven!$A$4:$E$7,MATCH($B33,Tarieven!$A$4:$A$7,0),4) | O33: =IFERROR($L33*$M33,0) | P33: =IFERROR($L33*$N33,0) | Q33: normaal | R33: 2026-06-09 | S33: 24 | T33: 52.41479 | U33: 4.8819 | V33: Neptunusstraat 2, Amsterdam | W33: Asfalt Schouw NOORD — 26 augustus 2026 | X33: 11/49 | Y33: 032-neptunusstraat.jpg | Z33: handgeschreven code "HB" in de kantlijn | AB33: SOK-AMS-NEPTUNUSSTRAAT | AD33: 3
A34: SOK-AMS-2026-033 | B34: Hotbox werkzaamheden | C34: Neptunusstraat | D34: Tuindorp Oostzaan | E34: Neptunesstr nr. 14 + 18 4.35 x 0,40 | F34: 4,35 × 0,40 m (samen 1,7 m²) | G34: 1 | H34: 4.35 | I34: 0.4 | J34: 1.74 | K34: =INDEX(Tarieven!$A$4:$E$7,MATCH($B34,Tarieven!$A$4:$A$7,0),2) | L34: =IF($K34="plek",$G34,IF($K34="m1",$H34,$J34)) | M34: =INDEX(Tarieven!$A$4:$E$7,MATCH($B34,Tarieven!$A$4:$A$7,0),3) | N34: =INDEX(Tarieven!$A$4:$E$7,MATCH($B34,Tarieven!$A$4:$A$7,0),4) | O34: =IFERROR($L34*$M34,0) | P34: =IFERROR($L34*$N34,0) | Q34: normaal | R34: 2026-06-10 | S34: 24 | T34: 52.4152 | U34: 4.88243 | V34: Neptunusstraat 14, Amsterdam | W34: Asfalt Schouw NOORD — 26 augustus 2026 | X34: 12/49 | Y34: 033-neptunusstraat.jpg | Z34: handgeschreven code "HB" in de kantlijn | AB34: SOK-AMS-NEPTUNUSSTRAAT | AD34: 1
A35: SOK-AMS-2026-034 | B35: Hotbox werkzaamheden | C35: Neptunusstraat | D35: Tuindorp Oostzaan | E35: Neptunusstr nr. 24 2.40 x 0.40 | F35: 2,40 × 0,40 m (samen 1,0 m²) | G35: 1 | H35: 2.4 | I35: 0.4 | J35: 0.96 | K35: =INDEX(Tarieven!$A$4:$E$7,MATCH($B35,Tarieven!$A$4:$A$7,0),2) | L35: =IF($K35="plek",$G35,IF($K35="m1",$H35,$J35)) | M35: =INDEX(Tarieven!$A$4:$E$7,MATCH($B35,Tarieven!$A$4:$A$7,0),3) | N35: =INDEX(Tarieven!$A$4:$E$7,MATCH($B35,Tarieven!$A$4:$A$7,0),4) | O35: =IFERROR($L35*$M35,0) | P35: =IFERROR($L35*$N35,0) | Q35: normaal | R35: 2026-06-10 | S35: 24 | T35: 52.41558 | U35: 4.88293 | V35: Neptunusstraat 24, Amsterdam | W35: Asfalt Schouw NOORD — 26 augustus 2026 | X35: 12/49 | Y35: 034-neptunusstraat.jpg | Z35: handgeschreven code "HB" in de kantlijn | AB35: SOK-AMS-NEPTUNUSSTRAAT | AD35: 1
A36: SOK-AMS-2026-035 | B36: Hotbox werkzaamheden | C36: Neptunusstraat | D36: Tuindorp Oostzaan | E36: Neptunusstr nr. 30 tot Uranusstr 15.25 x 0.60 | F36: 15,25 × 0,60 m (samen 9,2 m²) | G36: 1 | H36: 15.25 | I36: 0.6 | J36: 9.15 | K36: =INDEX(Tarieven!$A$4:$E$7,MATCH($B36,Tarieven!$A$4:$A$7,0),2) | L36: =IF($K36="plek",$G36,IF($K36="m1",$H36,$J36)) | M36: =INDEX(Tarieven!$A$4:$E$7,MATCH($B36,Tarieven!$A$4:$A$7,0),3) | N36: =INDEX(Tarieven!$A$4:$E$7,MATCH($B36,Tarieven!$A$4:$A$7,0),4) | O36: =IFERROR($L36*$M36,0) | P36: =IFERROR($L36*$N36,0) | Q36: normaal | R36: 2026-06-10 | S36: 24 | T36: 52.41558 | U36: 4.88293 | V36: Neptunusstraat 24, Amsterdam | W36: Asfalt Schouw NOORD — 26 augustus 2026 | X36: 12/49 | Y36: 035-neptunusstraat.jpg | Z36: handgeschreven code "HB" in de kantlijn | AB36: SOK-AMS-NEPTUNUSSTRAAT | AD36: 1
A37: SOK-AMS-2026-036 | B37: Asfalt machinaal | C37: Uranusstraat | D37: Tuindorp Oostzaan | E37: Uranusstr nr 32 tot nr. 10 62.50 x. 1 00 foto 1. Nr 1 tot Kometensingel 18 00 x 1.50 foto 2 | G37: 0 | K37: =INDEX(Tarieven!$A$4:$E$7,MATCH($B37,Tarieven!$A$4:$A$7,0),2) | L37: =IF($K37="plek",$G37,IF($K37="m1",$H37,$J37)) | M37: =INDEX(Tarieven!$A$4:$E$7,MATCH($B37,Tarieven!$A$4:$A$7,0),3) | N37: =INDEX(Tarieven!$A$4:$E$7,MATCH($B37,Tarieven!$A$4:$A$7,0),4) | O37: =IFERROR($L37*$M37,0) | P37: =IFERROR($L37*$N37,0) | Q37: normaal | R37: 2026-06-10 | S37: 24 | T37: 52.41574 | U37: 4.88308 | V37: Uranusstraat 31, Amsterdam | W37: Asfalt Schouw NOORD — 26 augustus 2026 | X37: 12/49 | Y37: 036-uranusstraat.jpg | Z37: handgeschreven code "AS" in de kantlijn | AA37: geen maatvoering in de bron | AB37: SOK-AMS-URANUSSTRAAT | AD37: 2
A38: SOK-AMS-2026-037 | B38: Hotbox werkzaamheden | C38: Mercuriusstraat | D38: Tuindorp Oostzaan | E38: Mercuriusstr nr. 43. 9.00 x 1.50 + 2.90 x 0.90 | F38: 9,00 × 1,50 m + 2,90 × 0,90 m (samen 16,1 m²) | G38: 2 | H38: 11.9 | I38: 0.9 | J38: 16.11 | K38: =INDEX(Tarieven!$A$4:$E$7,MATCH($B38,Tarieven!$A$4:$A$7,0),2) | L38: =IF($K38="plek",$G38,IF($K38="m1",$H38,$J38)) | M38: =INDEX(Tarieven!$A$4:$E$7,MATCH($B38,Tarieven!$A$4:$A$7,0),3) | N38: =INDEX(Tarieven!$A$4:$E$7,MATCH($B38,Tarieven!$A$4:$A$7,0),4) | O38: =IFERROR($L38*$M38,0) | P38: =IFERROR($L38*$N38,0) | Q38: normaal | R38: 2026-06-10 | S38: 24 | T38: 52.41507 | U38: 4.88429 | V38: Kometensingel 209, Amsterdam | W38: Asfalt Schouw NOORD — 26 augustus 2026 | X38: 13/49 | Y38: 037-mercuriusstraat.jpg | Z38: handgeschreven code "HB" in de kantlijn | AB38: SOK-AMS-MERCURIUSSTRAAT | AD38: 2
A39: SOK-AMS-2026-038 | B39: Hotbox werkzaamheden | C39: Saturnusstraat | D39: Tuindorp Oostzaan | E39: Saturnusstr nr. 1. 10.80 x 1.70 + 7.85 x 0.80 | F39: 10,80 × 1,70 m + 7,85 × 0,80 m (samen 24,6 m²) | G39: 2 | H39: 18.65 | I39: 0.8 | J39: 24.64 | K39: =INDEX(Tarieven!$A$4:$E$7,MATCH($B39,Tarieven!$A$4:$A$7,0),2) | L39: =IF($K39="plek",$G39,IF($K39="m1",$H39,$J39)) | M39: =INDEX(Tarieven!$A$4:$E$7,MATCH($B39,Tarieven!$A$4:$A$7,0),3) | N39: =INDEX(Tarieven!$A$4:$E$7,MATCH($B39,Tarieven!$A$4:$A$7,0),4) | O39: =IFERROR($L39*$M39,0) | P39: =IFERROR($L39*$N39,0) | Q39: normaal | R39: 2026-06-10 | S39: 24 | T39: 52.41518 | U39: 4.88411 | V39: Mercuriusstraat 43, Amsterdam | W39: Asfalt Schouw NOORD — 26 augustus 2026 | X39: 13/49 | Y39: 038-saturnusstraat.jpg | Z39: handgeschreven code "HB" in de kantlijn | AB39: SOK-AMS-SATURNUSSTRAAT | AD39: 2
A40: SOK-AMS-2026-039 | B40: Hotbox werkzaamheden | C40: Marsstraat | D40: Tuindorp Oostzaan | E40: Marsstr nr. 18 2x 2.20 x 0.45 | F40: 2× 2,20 × 0,45 m (samen 2,0 m²) | G40: 2 | H40: 4.4 | I40: 0.45 | J40: 1.98 | K40: =INDEX(Tarieven!$A$4:$E$7,MATCH($B40,Tarieven!$A$4:$A$7,0),2) | L40: =IF($K40="plek",$G40,IF($K40="m1",$H40,$J40)) | M40: =INDEX(Tarieven!$A$4:$E$7,MATCH($B40,Tarieven!$A$4:$A$7,0),3) | N40: =INDEX(Tarieven!$A$4:$E$7,MATCH($B40,Tarieven!$A$4:$A$7,0),4) | O40: =IFERROR($L40*$M40,0) | P40: =IFERROR($L40*$N40,0) | Q40: normaal | R40: 2026-07-20 | S40: 30 | T40: 52.41504 | U40: 4.88235 | V40: Marsstraat 20, Amsterdam | W40: Asfalt Schouw NOORD — 26 augustus 2026 | X40: 14/49 | Y40: 039-marsstraat.jpg | Z40: handgeschreven code "HB" in de kantlijn | AB40: SOK-AMS-MARSSTRAAT | AD40: 2
...

Sheet Per werksoort
A1: Samenvatting per werksoort
A3: Werksoort | B3: Aantal locaties | C3: Vlakken | D3: Lengte (m) | E3: Oppervlak (m2) | F3: Kosten min | G3: Kosten max
A4: Hotbox werkzaamheden | B4: =COUNTIF(Locaties!$B$2:$B$157,$A4) | C4: =SUMIF(Locaties!$B$2:$B$157,$A4,Locaties!$G$2:$G$157) | D4: =SUMIF(Locaties!$B$2:$B$157,$A4,Locaties!$H$2:$H$157) | E4: =SUMIF(Locaties!$B$2:$B$157,$A4,Locaties!$J$2:$J$157) | F4: =SUMIF(Locaties!$B$2:$B$157,$A4,Locaties!$O$2:$O$157) | G4: =SUMIF(Locaties!$B$2:$B$157,$A4,Locaties!$P$2:$P$157)
A5: Asfalt machinaal | B5: =COUNTIF(Locaties!$B$2:$B$157,$A5) | C5: =SUMIF(Locaties!$B$2:$B$157,$A5,Locaties!$G$2:$G$157) | D5: =SUMIF(Locaties!$B$2:$B$157,$A5,Locaties!$H$2:$H$157) | E5: =SUMIF(Locaties!$B$2:$B$157,$A5,Locaties!$J$2:$J$157) | F5: =SUMIF(Locaties!$B$2:$B$157,$A5,Locaties!$O$2:$O$157) | G5: =SUMIF(Locaties!$B$2:$B$157,$A5,Locaties!$P$2:$P$157)
A6: Scheuren vullen | B6: =COUNTIF(Locaties!$B$2:$B$157,$A6) | C6: =SUMIF(Locaties!$B$2:$B$157,$A6,Locaties!$G$2:$G$157) | D6: =SUMIF(Locaties!$B$2:$B$157,$A6,Locaties!$H$2:$H$157) | E6: =SUMIF(Locaties!$B$2:$B$157,$A6,Locaties!$J$2:$J$157) | F6: =SUMIF(Locaties!$B$2:$B$157,$A6,Locaties!$O$2:$O$157) | G6: =SUMIF(Locaties!$B$2:$B$157,$A6,Locaties!$P$2:$P$157)
A7: Asfalt – nog in te delen | B7: =COUNTIF(Locaties!$B$2:$B$157,$A7) | C7: =SUMIF(Locaties!$B$2:$B$157,$A7,Locaties!$G$2:$G$157) | D7: =SUMIF(Locaties!$B$2:$B$157,$A7,Locaties!$H$2:$H$157) | E7: =SUMIF(Locaties!$B$2:$B$157,$A7,Locaties!$J$2:$J$157) | F7: =SUMIF(Locaties!$B$2:$B$157,$A7,Locaties!$O$2:$O$157) | G7: =SUMIF(Locaties!$B$2:$B$157,$A7,Locaties!$P$2:$P$157)
A8: Totaal | B8: =SUM(B4:B7) | C8: =SUM(C4:C7) | D8: =SUM(D4:D7) | E8: =SUM(E4:E7) | F8: =SUM(F4:F7) | G8: =SUM(G4:G7)

Sheet Per asfaltsoort
A1: Rood asfalt tegenover zwart asfalt
A2: Het bronrapport noemt de asfaltsoort alleen bij de herstelpunten van de nutsbedrijven. Bij de rest staat het er niet.
A4: Asfaltsoort | B4: Aantal locaties | C4: Percentage | D4: Oppervlak (m2) | E4: Kosten min | F4: Kosten max
A5: zwart (rijweg) | B5: =COUNTIF(Locaties!$AC$2:$AC$157,$A5) | C5: =IFERROR($B5/$B$8,0) | D5: =SUMIF(Locaties!$AC$2:$AC$157,$A5,Locaties!$J$2:$J$157) | E5: =SUMIF(Locaties!$AC$2:$AC$157,$A5,Locaties!$O$2:$O$157) | F5: =SUMIF(Locaties!$AC$2:$AC$157,$A5,Locaties!$P$2:$P$157)
A6: rood (fiets-/voetpad) | B6: =COUNTIF(Locaties!$AC$2:$AC$157,$A6) | C6: =IFERROR($B6/$B$8,0) | D6: =SUMIF(Locaties!$AC$2:$AC$157,$A6,Locaties!$J$2:$J$157) | E6: =SUMIF(Locaties!$AC$2:$AC$157,$A6,Locaties!$O$2:$O$157) | F6: =SUMIF(Locaties!$AC$2:$AC$157,$A6,Locaties!$P$2:$P$157)
A7: niet vermeld in het rapport | B7: =$B$8-SUM(B5:B6) | C7: =IFERROR($B7/$B$8,0) | D7: =SUM(Locaties!$J$2:$J$157)-SUM(D5:D6) | E7: =SUM(Locaties!$O$2:$O$157)-SUM(E5:E6) | F7: =SUM(Locaties!$P$2:$P$157)-SUM(F5:F6)
A8: Totaal (alle locaties) | B8: =COUNTA(Locaties!$A$2:$A$157) | C8: =SUM(C5:C7) | D8: =SUM(Locaties!$J$2:$J$157) | E8: =SUM(Locaties!$O$2:$O$157) | F8: =SUM(Locaties!$P$2:$P$157)

Sheet Per weg
A1: Samenvatting per weg
A3: Weg | B3: Buurt | C3: Aantal locaties | D3: Oppervlak (m2) | E3: Kosten min | F3: Kosten max | G3: Conditie (afgeleid)
A4: Aldebaranplein | B4: Amsterdam-Noord — Tuindorp Oostzaan | C4: =COUNTIF(Locaties!$C$2:$C$157,$A4) | D4: =SUMIF(Locaties!$C$2:$C$157,$A4,Locaties!$J$2:$J$157) | E4: =SUMIF(Locaties!$C$2:$C$157,$A4,Locaties!$O$2:$O$157) | F4: =SUMIF(Locaties!$C$2:$C$157,$A4,Locaties!$P$2:$P$157) | G4: 2
A5: Aldebaranstraat | B5: Amsterdam-Noord — Tuindorp Oostzaan | C5: =COUNTIF(Locaties!$C$2:$C$157,$A5) | D5: =SUMIF(Locaties!$C$2:$C$157,$A5,Locaties!$J$2:$J$157) | E5: =SUMIF(Locaties!$C$2:$C$157,$A5,Locaties!$O$2:$O$157) | F5: =SUMIF(Locaties!$C$2:$C$157,$A5,Locaties!$P$2:$P$157) | G5: 4
A6: Appelweg | B6: Amsterdam-Noord — Tuindorp Oostzaan | C6: =COUNTIF(Locaties!$C$2:$C$157,$A6) | D6: =SUMIF(Locaties!$C$2:$C$157,$A6,Locaties!$J$2:$J$157) | E6: =SUMIF(Locaties!$C$2:$C$157,$A6,Locaties!$O$2:$O$157) | F6: =SUMIF(Locaties!$C$2:$C$157,$A6,Locaties!$P$2:$P$157) | G6: 2
A7: Argostraat | B7: Amsterdam-Noord — Tuindorp Oostzaan | C7: =COUNTIF(Locaties!$C$2:$C$157,$A7) | D7: =SUMIF(Locaties!$C$2:$C$157,$A7,Locaties!$J$2:$J$157) | E7: =SUMIF(Locaties!$C$2:$C$157,$A7,Locaties!$O$2:$O$157) | F7: =SUMIF(Locaties!$C$2:$C$157,$A7,Locaties!$P$2:$P$157) | G7: 3
A8: Astasiastraat | B8: Amsterdam-Noord — Kadoelen | C8: =COUNTIF(Locaties!$C$2:$C$157,$A8) | D8: =SUMIF(Locaties!$C$2:$C$157,$A8,Locaties!$J$2:$J$157) | E8: =SUMIF(Locaties!$C$2:$C$157,$A8,Locaties!$O$2:$O$157) | F8: =SUMIF(Locaties!$C$2:$C$157,$A8,Locaties!$P$2:$P$157) | G8: 4
A9: Baanakkerspad | B9: Amsterdam-Noord | C9: =COUNTIF(Locaties!$C$2:$C$157,$A9) | D9: =SUMIF(Locaties!$C$2:$C$157,$A9,Locaties!$J$2:$J$157) | E9: =SUMIF(Locaties!$C$2:$C$157,$A9,Locaties!$O$2:$O$157) | F9: =SUMIF(Locaties!$C$2:$C$157,$A9,Locaties!$P$2:$P$157) | G9: 2
A10: Buiksloterdijk | B10: Amsterdam-Noord — Asfalt Schades Heel Noord, Kadoelen | C10: =COUNTIF(Locaties!$C$2:$C$157,$A10) | D10: =SUMIF(Locaties!$C$2:$C$157,$A10,Locaties!$J$2:$J$157) | E10: =SUMIF(Locaties!$C$2:$C$157,$A10,Locaties!$O$2:$O$157) | F10: =SUMIF(Locaties!$C$2:$C$157,$A10,Locaties!$P$2:$P$157) | G10: 4
A11: Castorplein | B11: Amsterdam-Noord — Tuindorp Oostzaan | C11: =COUNTIF(Locaties!$C$2:$C$157,$A11) | D11: =SUMIF(Locaties!$C$2:$C$157,$A11,Locaties!$J$2:$J$157) | E11: =SUMIF(Locaties!$C$2:$C$157,$A11,Locaties!$O$2:$O$157) | F11: =SUMIF(Locaties!$C$2:$C$157,$A11,Locaties!$P$2:$P$157) | G11: 2
A12: Cornelis Roosstraat | B12: Amsterdam-Noord — Oostzanerwerf | C12: =COUNTIF(Locaties!$C$2:$C$157,$A12) | D12: =SUMIF(Locaties!$C$2:$C$157,$A12,Locaties!$J$2:$J$157) | E12: =SUMIF(Locaties!$C$2:$C$157,$A12,Locaties!$O$2:$O$157) | F12: =SUMIF(Locaties!$C$2:$C$157,$A12,Locaties!$P$2:$P$157) | G12: 3
A13: Eudorinastraat | B13: Amsterdam-Noord — Kadoelen | C13: =COUNTIF(Locaties!$C$2:$C$157,$A13) | D13: =SUMIF(Locaties!$C$2:$C$157,$A13,Locaties!$J$2:$J$157) | E13: =SUMIF(Locaties!$C$2:$C$157,$A13,Locaties!$O$2:$O$157) | F13: =SUMIF(Locaties!$C$2:$C$157,$A13,Locaties!$P$2:$P$157) | G13: 3
A14: Floraweg | B14: Amsterdam-Noord | C14: =COUNTIF(Locaties!$C$2:$C$157,$A14) | D14: =SUMIF(Locaties!$C$2:$C$157,$A14,Locaties!$J$2:$J$157) | E14: =SUMIF(Locaties!$C$2:$C$157,$A14,Locaties!$O$2:$O$157) | F14: =SUMIF(Locaties!$C$2:$C$157,$A14,Locaties!$P$2:$P$157) | G14: 2
A15: Grote Beerstraat | B15: Amsterdam-Noord — Tuindorp Oostzaan | C15: =COUNTIF(Locaties!$C$2:$C$157,$A15) | D15: =SUMIF(Locaties!$C$2:$C$157,$A15,Locaties!$J$2:$J$157) | E15: =SUMIF(Locaties!$C$2:$C$157,$A15,Locaties!$O$2:$O$157) | F15: =SUMIF(Locaties!$C$2:$C$157,$A15,Locaties!$P$2:$P$157) | G15: 2
... A51: Zuideinde | B51: Amsterdam-Noord — Oostzanerwerf | C51: =COUNTIF(Locaties!$C$2:$C$157,$A51) | D51: =SUMIF(Locaties!$C$2:$C$157,$A51,Locaties!$J$2:$J$157) | E51: =SUMIF(Locaties!$C$2:$C$157,$A51,Locaties!$O$2:$O$157) | F51: =SUMIF(Locaties!$C$2:$C$157,$A51,Locaties!$P$2:$P$157) | G51: 3
A52: Totaal | C52: =SUM(C4:C51) | D52: =SUM(D4:D51) | E52: =SUM(E4:E51) | F52: =SUM(F4:F51)
A54: Conditie is afgeleid uit het geschouwde schadeoppervlak per weg, niet uit een NEN 2767-inspectie. Zie het blad Toelichting.
